Workbook

Sheet Comparación
A1: SKU | B1: Planta | C1: Mes | D1: Real (TO) | E1: Planificador (TO) | F1: Modelo interno (TO) | G1: Nuestro modelo ml_mean (TO) | H1: Tiene interno | I1: Error planificador (TO) | J1: Error modelo interno (TO) | K1: Error nuestro modelo (TO) | L1: Error abs. planificador (TO) | M1: Error abs. modelo interno (TO) | N1: Error abs. nuestro modelo (TO) | O1: Error % planificador | P1: Error % modelo interno | Q1: Error % nuestro modelo
A2: HP2/01/115gsm/2190mm | B2: PCEL | C2: 2026-09 | D2: 105.823 | E2: 112 | F2: 112 | G2: 126.895 | H2: =ISNUMBER(F2) | I2: =E2-D2 | J2: =IF(ISNUMBER(F2),F2-D2,"") | K2: =G2-D2 | L2: =ABS(I2) | M2: =IF(ISNUMBER(F2),ABS(F2-D2),"") | N2: =ABS(K2) | O2: =IF(D2=0,"",(E2-D2)/D2) | P2: =IF(ISNUMBER(F2),IF(D2=0,"",(F2-D2)/D2),"") | Q2: =IF(D2=0,"",(G2-D2)/D2)
A3: HP2/01/115gsm/2440mm | B3: PCEL | C3: 2026-09 | D3: 216.365 | E3: 157 | F3: 157 | G3: 180.58 | H3: =ISNUMBER(F3) | I3: =E3-D3 | J3: =IF(ISNUMBER(F3),F3-D3,"") | K3: =G3-D3 | L3: =ABS(I3) | M3: =IF(ISNUMBER(F3),ABS(F3-D3),"") | N3: =ABS(K3) | O3: =IF(D3=0,"",(E3-D3)/D3) | P3: =IF(ISNUMBER(F3),IF(D3=0,"",(F3-D3)/D3),"") | Q3: =IF(D3=0,"",(G3-D3)/D3)
A4: HP2/01/125gsm/2190mm | B4: PCEL | C4: 2026-09 | D4: 108.147 | E4: 100 | F4: 193 | G4: 151.441 | H4: =ISNUMBER(F4) | I4: =E4-D4 | J4: =IF(ISNUMBER(F4),F4-D4,"") | K4: =G4-D4 | L4: =ABS(I4) | M4: =IF(ISNUMBER(F4),ABS(F4-D4),"") | N4: =ABS(K4) | O4: =IF(D4=0,"",(E4-D4)/D4) | P4: =IF(ISNUMBER(F4),IF(D4=0,"",(F4-D4)/D4),"") | Q4: =IF(D4=0,"",(G4-D4)/D4)
A5: HP2/01/125gsm/2440mm | B5: PCEL | C5: 2026-09 | D5: 157.307 | E5: 100 | F5: 236 | G5: 150.24 | H5: =ISNUMBER(F5) | I5: =E5-D5 | J5: =IF(ISNUMBER(F5),F5-D5,"") | K5: =G5-D5 | L5: =ABS(I5) | M5: =IF(ISNUMBER(F5),ABS(F5-D5),"") | N5: =ABS(K5) | O5: =IF(D5=0,"",(E5-D5)/D5) | P5: =IF(ISNUMBER(F5),IF(D5=0,"",(F5-D5)/D5),"") | Q5: =IF(D5=0,"",(G5-D5)/D5)
A6: HP2/01/155gsm/2190mm | B6: PCEL | C6: 2026-09 | D6: 94.195 | E6: 160 | F6: 255 | G6: 178.823 | H6: =ISNUMBER(F6) | I6: =E6-D6 | J6: =IF(ISNUMBER(F6),F6-D6,"") | K6: =G6-D6 | L6: =ABS(I6) | M6: =IF(ISNUMBER(F6),ABS(F6-D6),"") | N6: =ABS(K6) | O6: =IF(D6=0,"",(E6-D6)/D6) | P6: =IF(ISNUMBER(F6),IF(D6=0,"",(F6-D6)/D6),"") | Q6: =IF(D6=0,"",(G6-D6)/D6)
A7: HP2/01/155gsm/2440mm | B7: PCEL | C7: 2026-09 | D7: 190.502 | E7: 135 | F7: 191 | G7: 142.041 | H7: =ISNUMBER(F7) | I7: =E7-D7 | J7: =IF(ISNUMBER(F7),F7-D7,"") | K7: =G7-D7 | L7: =ABS(I7) | M7: =IF(ISNUMBER(F7),ABS(F7-D7),"") | N7: =ABS(K7) | O7: =IF(D7=0,"",(E7-D7)/D7) | P7: =IF(ISNUMBER(F7),IF(D7=0,"",(F7-D7)/D7),"") | Q7: =IF(D7=0,"",(G7-D7)/D7)
A8: K/01/110gsm/2000mm | B8: PCEL | C8: 2026-09 | D8: 14.545 | E8: 25 | F8: 37 | G8: 18.836 | H8: =ISNUMBER(F8) | I8: =E8-D8 | J8: =IF(ISNUMBER(F8),F8-D8,"") | K8: =G8-D8 | L8: =ABS(I8) | M8: =IF(ISNUMBER(F8),ABS(F8-D8),"") | N8: =ABS(K8) | O8: =IF(D8=0,"",(E8-D8)/D8) | P8: =IF(ISNUMBER(F8),IF(D8=0,"",(F8-D8)/D8),"") | Q8: =IF(D8=0,"",(G8-D8)/D8)
A9: K/01/110gsm/2200mm | B9: PCEL | C9: 2026-09 | D9: 44.145 | E9: 55 | F9: 54 | G9: 35.16 | H9: =ISNUMBER(F9) | I9: =E9-D9 | J9: =IF(ISNUMBER(F9),F9-D9,"") | K9: =G9-D9 | L9: =ABS(I9) | M9: =IF(ISNUMBER(F9),ABS(F9-D9),"") | N9: =ABS(K9) | O9: =IF(D9=0,"",(E9-D9)/D9) | P9: =IF(ISNUMBER(F9),IF(D9=0,"",(F9-D9)/D9),"") | Q9: =IF(D9=0,"",(G9-D9)/D9)
A10: K/01/110gsm/2450mm | B10: PCEL | C10: 2026-09 | D10: 62.695 | E10: 75 | F10: 82 | G10: 56.49 | H10: =ISNUMBER(F10) | I10: =E10-D10 | J10: =IF(ISNUMBER(F10),F10-D10,"") | K10: =G10-D10 | L10: =ABS(I10) | M10: =IF(ISNUMBER(F10),ABS(F10-D10),"") | N10: =ABS(K10) | O10: =IF(D10=0,"",(E10-D10)/D10) | P10: =IF(ISNUMBER(F10),IF(D10=0,"",(F10-D10)/D10),"") | Q10: =IF(D10=0,"",(G10-D10)/D10)
A11: K/01/125gsm/2200mm | B11: PCEL | C11: 2026-09 | D11: 44.59 | E11: 50 | F11: 76 | G11: 42.548 | H11: =ISNUMBER(F11) | I11: =E11-D11 | J11: =IF(ISNUMBER(F11),F11-D11,"") | K11: =G11-D11 | L11: =ABS(I11) | M11: =IF(ISNUMBER(F11),ABS(F11-D11),"") | N11: =ABS(K11) | O11: =IF(D11=0,"",(E11-D11)/D11) | P11: =IF(ISNUMBER(F11),IF(D11=0,"",(F11-D11)/D11),"") | Q11: =IF(D11=0,"",(G11-D11)/D11)
A12: K/01/125gsm/2450mm | B12: PCEL | C12: 2026-09 | D12: 88.179 | E12: 100 | F12: 59 | G12: 46.566 | H12: =ISNUMBER(F12) | I12: =E12-D12 | J12: =IF(ISNUMBER(F12),F12-D12,"") | K12: =G12-D12 | L12: =ABS(I12) | M12: =IF(ISNUMBER(F12),ABS(F12-D12),"") | N12: =ABS(K12) | O12: =IF(D12=0,"",(E12-D12)/D12) | P12: =IF(ISNUMBER(F12),IF(D12=0,"",(F12-D12)/D12),"") | Q12: =IF(D12=0,"",(G12-D12)/D12)
A13: K/01/160gsm/2000mm | B13: PCEL | C13: 2026-09 | D13: 34.525 | E13: 45 | F13: 70 | G13: 48.4 | H13: =ISNUMBER(F13) | I13: =E13-D13 | J13: =IF(ISNUMBER(F13),F13-D13,"") | K13: =G13-D13 | L13: =ABS(I13) | M13: =IF(ISNUMBER(F13),ABS(F13-D13),"") | N13: =ABS(K13) | O13: =IF(D13=0,"",(E13-D13)/D13) | P13: =IF(ISNUMBER(F13),IF(D13=0,"",(F13-D13)/D13),"") | Q13: =IF(D13=0,"",(G13-D13)/D13)
... A30: HP2/01/155gsm/2440mm | B30: SALC | C30: 2026-09 | D30: 328.631 | E30: 311 | F30: 168 | G30: 291.567 | H30: =ISNUMBER(F30) | I30: =E30-D30 | J30: =IF(ISNUMBER(F30),F30-D30,"") | K30: =G30-D30 | L30: =ABS(I30) | M30: =IF(ISNUMBER(F30),ABS(F30-D30),"") | N30: =ABS(K30) | O30: =IF(D30=0,"",(E30-D30)/D30) | P30: =IF(ISNUMBER(F30),IF(D30=0,"",(F30-D30)/D30),"") | Q30: =IF(D30=0,"",(G30-D30)/D30)
A31: HP2/01/155gsm/2500mm | B31: SALC | C31: 2026-09 | D31: 109.376 | E31: 110 | F31: faltante | G31: 94.189 | H31: =ISNUMBER(F31) | I31: =E31-D31 | J31: =IF(ISNUMBER(F31),F31-D31,"") | K31: =G31-D31 | L31: =ABS(I31) | M31: =IF(ISNUMBER(F31),ABS(F31-D31),"") | N31: =ABS(K31) | O31: =IF(D31=0,"",(E31-D31)/D31) | P31: =IF(ISNUMBER(F31),IF(D31=0,"",(F31-D31)/D31),"") | Q31: =IF(D31=0,"",(G31-D31)/D31)
A32: K/01/110gsm/2300mm | B32: SALC | C32: 2026-09 | D32: 38.591 | E32: 40 | F32: 35 | G32: 38.813 | H32: =ISNUMBER(F32) | I32: =E32-D32 | J32: =IF(ISNUMBER(F32),F32-D32,"") | K32: =G32-D32 | L32: =ABS(I32) | M32: =IF(ISNUMBER(F32),ABS(F32-D32),"") | N32: =ABS(K32) | O32: =IF(D32=0,"",(E32-D32)/D32) | P32: =IF(ISNUMBER(F32),IF(D32=0,"",(F32-D32)/D32),"") | Q32: =IF(D32=0,"",(G32-D32)/D32)
A33: K/01/110gsm/2450mm | B33: SALC | C33: 2026-09 | D33: 24.528 | E33: 28 | F33: 32 | G33: 26.554 | H33: =ISNUMBER(F33) | I33: =E33-D33 | J33: =IF(ISNUMBER(F33),F33-D33,"") | K33: =G33-D33 | L33: =ABS(I33) | M33: =IF(ISNUMBER(F33),ABS(F33-D33),"") | N33: =ABS(K33) | O33: =IF(D33=0,"",(E33-D33)/D33) | P33: =IF(ISNUMBER(F33),IF(D33=0,"",(F33-D33)/D33),"") | Q33: =IF(D33=0,"",(G33-D33)/D33)
A34: K/01/200gsm/2300mm | B34: SALC | C34: 2026-09 | D34: 68.876 | E34: 58 | F34: 51 | G34: 51.243 | H34: =ISNUMBER(F34) | I34: =E34-D34 | J34: =IF(ISNUMBER(F34),F34-D34,"") | K34: =G34-D34 | L34: =ABS(I34) | M34: =IF(ISNUMBER(F34),ABS(F34-D34),"") | N34: =ABS(K34) | O34: =IF(D34=0,"",(E34-D34)/D34) | P34: =IF(ISNUMBER(F34),IF(D34=0,"",(F34-D34)/D34),"") | Q34: =IF(D34=0,"",(G34-D34)/D34)
A35: K/01/225gsm/2300mm | B35: SALC | C35: 2026-09 | D35: 29.654 | E35: 35 | F35: 33 | G35: 36.25 | H35: =ISNUMBER(F35) | I35: =E35-D35 | J35: =IF(ISNUMBER(F35),F35-D35,"") | K35: =G35-D35 | L35: =ABS(I35) | M35: =IF(ISNUMBER(F35),ABS(F35-D35),"") | N35: =ABS(K35) | O35: =IF(D35=0,"",(E35-D35)/D35) | P35: =IF(ISNUMBER(F35),IF(D35=0,"",(F35-D35)/D35),"") | Q35: =IF(D35=0,"",(G35-D35)/D35)
A36: K/01/225gsm/2450mm | B36: SALC | C36: 2026-09 | D36: 20.96 | E36: 35 | F36: 45 | G36: 30.491 | H36: =ISNUMBER(F36) | I36: =E36-D36 | J36: =IF(ISNUMBER(F36),F36-D36,"") | K36: =G36-D36 | L36: =ABS(I36) | M36: =IF(ISNUMBER(F36),ABS(F36-D36),"") | N36: =ABS(K36) | O36: =IF(D36=0,"",(E36-D36)/D36) | P36: =IF(ISNUMBER(F36),IF(D36=0,"",(F36-D36)/D36),"") | Q36: =IF(D36=0,"",(G36-D36)/D36)
A37: KW2/01/115gsm/2000mm | B37: SALC | C37: 2026-09 | D37: 54.251 | E37: 72 | F37: 67 | G37: 64.595 | H37: =ISNUMBER(F37) | I37: =E37-D37 | J37: =IF(ISNUMBER(F37),F37-D37,"") | K37: =G37-D37 | L37: =ABS(I37) | M37: =IF(ISNUMBER(F37),ABS(F37-D37),"") | N37: =ABS(K37) | O37: =IF(D37=0,"",(E37-D37)/D37) | P37: =IF(ISNUMBER(F37),IF(D37=0,"",(F37-D37)/D37),"") | Q37: =IF(D37=0,"",(G37-D37)/D37)
A38: KW2/01/115gsm/2300mm | B38: SALC | C38: 2026-09 | D38: 80.065 | E38: 120 | F38: 104 | G38: 109.189 | H38: =ISNUMBER(F38) | I38: =E38-D38 | J38: =IF(ISNUMBER(F38),F38-D38,"") | K38: =G38-D38 | L38: =ABS(I38) | M38: =IF(ISNUMBER(F38),ABS(F38-D38),"") | N38: =ABS(K38) | O38: =IF(D38=0,"",(E38-D38)/D38) | P38: =IF(ISNUMBER(F38),IF(D38=0,"",(F38-D38)/D38),"") | Q38: =IF(D38=0,"",(G38-D38)/D38)
A39: KW2/01/115gsm/2450mm | B39: SALC | C39: 2026-09 | D39: 206.063 | E39: 215 | F39: 223 | G39: 218.212 | H39: =ISNUMBER(F39) | I39: =E39-D39 | J39: =IF(ISNUMBER(F39),F39-D39,"") | K39: =G39-D39 | L39: =ABS(I39) | M39: =IF(ISNUMBER(F39),ABS(F39-D39),"") | N39: =ABS(K39) | O39: =IF(D39=0,"",(E39-D39)/D39) | P39: =IF(ISNUMBER(F39),IF(D39=0,"",(F39-D39)/D39),"") | Q39: =IF(D39=0,"",(G39-D39)/D39)
A40: KW2/01/160gsm/2300mm | B40: SALC | C40: 2026-09 | D40: 123.09 | E40: 128 | F40: 17 | G40: 122.897 | H40: =ISNUMBER(F40) | I40: =E40-D40 | J40: =IF(ISNUMBER(F40),F40-D40,"") | K40: =G40-D40 | L40: =ABS(I40) | M40: =IF(ISNUMBER(F40),ABS(F40-D40),"") | N40: =ABS(K40) | O40: =IF(D40=0,"",(E40-D40)/D40) | P40: =IF(ISNUMBER(F40),IF(D40=0,"",(F40-D40)/D40),"") | Q40: =IF(D40=0,"",(G40-D40)/D40)
A41: KW2/01/160gsm/2450mm | B41: SALC | C41: 2026-09 | D41: 153.916 | E41: 100 | F41: 25 | G41: 110.861 | H41: =ISNUMBER(F41) | I41: =E41-D41 | J41: =IF(ISNUMBER(F41),F41-D41,"") | K41: =G41-D41 | L41: =ABS(I41) | M41: =IF(ISNUMBER(F41),ABS(F41-D41),"") | N41: =ABS(K41) | O41: =IF(D41=0,"",(E41-D41)/D41) | P41: =IF(ISNUMBER(F41),IF(D41=0,"",(F41-D41)/D41),"") | Q41: =IF(D41=0,"",(G41-D41)/D41)
A42: KW2/01/160gsm/2500mm | B42: SALC | C42: 2026-09 | D42: 166.245 | E42: 150 | F42: faltante | G42: 119.004 | H42: =ISNUMBER(F42) | I42: =E42-D42 | J42: =IF(ISNUMBER(F42),F42-D42,"") | K42: =G42-D42 | L42: =ABS(I42) | M42: =IF(ISNUMBER(F42),ABS(F42-D42),"") | N42: =ABS(K42) | O42: =IF(D42=0,"",(E42-D42)/D42) | P42: =IF(ISNUMBER(F42),IF(D42=0,"",(F42-D42)/D42),"") | Q42: =IF(D42=0,"",(G42-D42)/D42)
A43: RF1/01/100gsm/1990mm | B43: SALC | C43: 2026-09 | D43: 71.707 | E43: 50 | F43: 33 | G43: 45.857 | H43: =ISNUMBER(F43) | I43: =E43-D43 | J43: =IF(ISNUMBER(F43),F43-D43,"") | K43: =G43-D43 | L43: =ABS(I43) | M43: =IF(ISNUMBER(F43),ABS(F43-D43),"") | N43: =ABS(K43) | O43: =IF(D43=0,"",(E43-D43)/D43) | P43: =IF(ISNUMBER(F43),IF(D43=0,"",(F43-D43)/D43),"") | Q43: =IF(D43=0,"",(G43-D43)/D43)
A44: RF1/01/100gsm/2290mm | B44: SALC | C44: 2026-09 | D44: 136.925 | E44: 222 | F44: 203 | G44: 186.555 | H44: =ISNUMBER(F44) | I44: =E44-D44 | J44: =IF(ISNUMBER(F44),F44-D44,"") | K44: =G44-D44 | L44: =ABS(I44) | M44: =IF(ISNUMBER(F44),ABS(F44-D44),"") | N44: =ABS(K44) | O44: =IF(D44=0,"",(E44-D44)/D44) | P44: =IF(ISNUMBER(F44),IF(D44=0,"",(F44-D44)/D44),"") | Q44: =IF(D44=0,"",(G44-D44)/D44)
A45: RF1/01/100gsm/2350mm | B45: SALC | C45: 2026-09 | D45: 136.067 | E45: 90 | F45: 130 | G45: 106.636 | H45: =ISNUMBER(F45) | I45: =E45-D45 | J45: =IF(ISNUMBER(F45),F45-D45,"") | K45: =G45-D45 | L45: =ABS(I45) | M45: =IF(ISNUMBER(F45),ABS(F45-D45),"") | N45: =ABS(K45) | O45: =IF(D45=0,"",(E45-D45)/D45) | P45: =IF(ISNUMBER(F45),IF(D45=0,"",(F45-D45)/D45),"") | Q45: =IF(D45=0,"",(G45-D45)/D45)
A46: RF1/01/100gsm/2440mm | B46: SALC | C46: 2026-09 | D46: 338.642 | E46: 373 | F46: 320 | G46: 274.613 | H46: =ISNUMBER(F46) | I46: =E46-D46 | J46: =IF(ISNUMBER(F46),F46-D46,"") | K46: =G46-D46 | L46: =ABS(I46) | M46: =IF(ISNUMBER(F46),ABS(F46-D46),"") | N46: =ABS(K46) | O46: =IF(D46=0,"",(E46-D46)/D46) | P46: =IF(ISNUMBER(F46),IF(D46=0,"",(F46-D46)/D46),"") | Q46: =IF(D46=0,"",(G46-D46)/D46)
A47: RF1/01/80gsm/2440mm | B47: SALC | C47: 2026-09 | D47: 30.455 | E47: 45 | F47: 43 | G47: 53.28 | H47: =ISNUMBER(F47) | I47: =E47-D47 | J47: =IF(ISNUMBER(F47),F47-D47,"") | K47: =G47-D47 | L47: =ABS(I47) | M47: =IF(ISNUMBER(F47),ABS(F47-D47),"") | N47: =ABS(K47) | O47: =IF(D47=0,"",(E47-D47)/D47) | P47: =IF(ISNUMBER(F47),IF(D47=0,"",(F47-D47)/D47),"") | Q47: =IF(D47=0,"",(G47-D47)/D47)
A48: TSL/01/100gsm/2300mm | B48: SALC | C48: 2026-09 | D48: 33.02 | E48: 65 | F48: 66 | G48: 48.214 | H48: =ISNUMBER(F48) | I48: =E48-D48 | J48: =IF(ISNUMBER(F48),F48-D48,"") | K48: =G48-D48 | L48: =ABS(I48) | M48: =IF(ISNUMBER(F48),ABS(F48-D48),"") | N48: =ABS(K48) | O48: =IF(D48=0,"",(E48-D48)/D48) | P48: =IF(ISNUMBER(F48),IF(D48=0,"",(F48-D48)/D48),"") | Q48: =IF(D48=0,"",(G48-D48)/D48)
A49: TSL/01/100gsm/2450mm | B49: SALC | C49: 2026-09 | D49: 95.138 | E49: 130 | F49: 119 | G49: 111.621 | H49: =ISNUMBER(F49) | I49: =E49-D49 | J49: =IF(ISNUMBER(F49),F49-D49,"") | K49: =G49-D49 | L49: =ABS(I49) | M49: =IF(ISNUMBER(F49),ABS(F49-D49),"") | N49: =ABS(K49) | O49: =IF(D49=0,"",(E49-D49)/D49) | P49: =IF(ISNUMBER(F49),IF(D49=0,"",(F49-D49)/D49),"") | Q49: =IF(D49=0,"",(G49-D49)/D49)
A50: TSL/01/125gsm/2000mm | B50: SALC | C50: 2026-09 | D50: 39.576 | E50: 32 | F50: 45 | G50: 37.163 | H50: =ISNUMBER(F50) | I50: =E50-D50 | J50: =IF(ISNUMBER(F50),F50-D50,"") | K50: =G50-D50 | L50: =ABS(I50) | M50: =IF(ISNUMBER(F50),ABS(F50-D50),"") | N50: =ABS(K50) | O50: =IF(D50=0,"",(E50-D50)/D50) | P50: =IF(ISNUMBER(F50),IF(D50=0,"",(F50-D50)/D50),"") | Q50: =IF(D50=0,"",(G50-D50)/D50)
A51: TSL/01/125gsm/2300mm | B51: SALC | C51: 2026-09 | D51: 137.43 | E51: 174 | F51: 175 | G51: 138.129 | H51: =ISNUMBER(F51) | I51: =E51-D51 | J51: =IF(ISNUMBER(F51),F51-D51,"") | K51: =G51-D51 | L51: =ABS(I51) | M51: =IF(ISNUMBER(F51),ABS(F51-D51),"") | N51: =ABS(K51) | O51: =IF(D51=0,"",(E51-D51)/D51) | P51: =IF(ISNUMBER(F51),IF(D51=0,"",(F51-D51)/D51),"") | Q51: =IF(D51=0,"",(G51-D51)/D51)
A52: TSL/01/125gsm/2350mm | B52: SALC | C52: 2026-09 | D52: 148.633 | E52: 125 | F52: 175 | G52: 143.472 | H52: =ISNUMBER(F52) | I52: =E52-D52 | J52: =IF(ISNUMBER(F52),F52-D52,"") | K52: =G52-D52 | L52: =ABS(I52) | M52: =IF(ISNUMBER(F52),ABS(F52-D52),"") | N52: =ABS(K52) | O52: =IF(D52=0,"",(E52-D52)/D52) | P52: =IF(ISNUMBER(F52),IF(D52=0,"",(F52-D52)/D52),"") | Q52: =IF(D52=0,"",(G52-D52)/D52)
A53: TSL/01/125gsm/2450mm | B53: SALC | C53: 2026-09 | D53: 268.69 | E53: 290 | F53: 259 | G53: 226.843 | H53: =ISNUMBER(F53) | I53: =E53-D53 | J53: =IF(ISNUMBER(F53),F53-D53,"") | K53: =G53-D53 | L53: =ABS(I53) | M53: =IF(ISNUMBER(F53),ABS(F53-D53),"") | N53: =ABS(K53) | O53: =IF(D53=0,"",(E53-D53)/D53) | P53: =IF(ISNUMBER(F53),IF(D53=0,"",(F53-D53)/D53),"") | Q53: =IF(D53=0,"",(G53-D53)/D53)
A54: TSL/01/150gsm/2000mm | B54: SALC | C54: 2026-09 | D54: 60.198 | E54: 33 | F54: 35 | G54: 31.266 | H54: =ISNUMBER(F54) | I54: =E54-D54 | J54: =IF(ISNUMBER(F54),F54-D54,"") | K54: =G54-D54 | L54: =ABS(I54) | M54: =IF(ISNUMBER(F54),ABS(F54-D54),"") | N54: =ABS(K54) | O54: =IF(D54=0,"",(E54-D54)/D54) | P54: =IF(ISNUMBER(F54),IF(D54=0,"",(F54-D54)/D54),"") | Q54: =IF(D54=0,"",(G54-D54)/D54)
... A56: TSL/01/150gsm/2450mm | B56: SALC | C56: 2026-09 | D56: 203.499 | E56: 210 | F56: 190 | G56: 182.517 | H56: =ISNUMBER(F56) | I56: =E56-D56 | J56: =IF(ISNUMBER(F56),F56-D56,"") | K56: =G56-D56 | L56: =ABS(I56) | M56: =IF(ISNUMBER(F56),ABS(F56-D56),"") | N56: =ABS(K56) | O56: =IF(D56=0,"",(E56-D56)/D56) | P56: =IF(ISNUMBER(F56),IF(D56=0,"",(F56-D56)/D56),"") | Q56: =IF(D56=0,"",(G56-D56)/D56)
A57: TW2000/51/115gsm/2000mm | B57: SALC | C57: 2026-09 | D57: 23.258 | E57: 25 | F57: faltante | G57: 13.338 | H57: =ISNUMBER(F57) | I57: =E57-D57 | J57: =IF(ISNUMBER(F57),F57-D57,"") | K57: =G57-D57 | L57: =ABS(I57) | M57: =IF(ISNUMBER(F57),ABS(F57-D57),"") | N57: =ABS(K57) | O57: =IF(D57=0,"",(E57-D57)/D57) | P57: =IF(ISNUMBER(F57),IF(D57=0,"",(F57-D57)/D57),"") | Q57: =IF(D57=0,"",(G57-D57)/D57)
...

Sheet Excluidos
A1: SKU | B1: Planta | C1: Mes | D1: Planificador (TO) | E1: Motivo | F1: Explicación
A2: TSL/01/100gsm/2200mm | B2: PCEL | C2: 2026-09 | D2: 90 | E2: Menos de 3 meses de historia | F2: El SKU tiene solo 2 meses de consumo antes del mes pronosticado y el modelo necesita al menos 3.
A3: TSL/01/100gsm/2450mm | B3: PCEL | C3: 2026-09 | D3: 190 | E3: Menos de 3 meses de historia | F3: El SKU tiene solo 2 meses de consumo antes del mes pronosticado y el modelo necesita al menos 3.
A4: TW2000/51/115gsm/2200mm | B4: PCEL | C4: 2026-09 | D4: 45 | E4: Menos de 3 meses de historia | F4: El SKU tiene solo 2 meses de consumo antes del mes pronosticado y el modelo necesita al menos 3.
A5: TW2000/51/115gsm/2450mm | B5: PCEL | C5: 2026-09 | D5: 60 | E5: Menos de 3 meses de historia | F5: El SKU tiene solo 2 meses de consumo antes del mes pronosticado y el modelo necesita al menos 3.
A6: HP2/01/155gsm/2500mm | B6: SALC | C6: 2026-09 | D6: 110 | E6: Modelo interno sin pronóstico | F6: El modelo interno tiene 0 en todos los meses para este SKU; se toma como sin pronóstico. Se muestra como faltante en la hoja de comparación y no cuenta en las métricas.
A7: KW2/01/160gsm/2500mm | B7: SALC | C7: 2026-09 | D7: 150 | E7: Modelo interno sin pronóstico | F7: El modelo interno tiene 0 en todos los meses para este SKU; se toma como sin pronóstico. Se muestra como faltante en la hoja de comparación y no cuenta en las métricas.
A8: TW2000/51/115gsm/2000mm | B8: SALC | C8: 2026-09 | D8: 25 | E8: Modelo interno sin pronóstico | F8: El SKU no está en el archivo del modelo interno. Se muestra como faltante en la hoja de comparación y no cuenta en las métricas.
A9: HP2/01/115gsm/1790mm | B9: SALI | C9: 2026-09 | D9: 88 | E9: Modelo interno sin pronóstico | F9: El modelo interno tiene 0 en todos los meses para este SKU; se toma como sin pronóstico. Se muestra como faltante en la hoja de comparación y no cuenta en las métricas.
A10: HP2/01/115gsm/1850mm | B10: SALI | C10: 2026-09 | D10: 110 | E10: Modelo interno sin pronóstico | F10: El modelo interno tiene 0 en todos los meses para este SKU; se toma como sin pronóstico. Se muestra como faltante en la hoja de comparación y no cuenta en las métricas.
A11: HP2/01/115gsm/1955mm | B11: SALI | C11: 2026-09 | D11: 90 | E11: Modelo interno sin pronóstico | F11: El modelo interno tiene 0 en todos los meses para este SKU; se toma como sin pronóstico. Se muestra como faltante en la hoja de comparación y no cuenta en las métricas.
A12: HP2/01/115gsm/2040mm | B12: SALI | C12: 2026-09 | D12: 56 | E12: Modelo interno sin pronóstico | F12: El modelo interno tiene 0 en todos los meses para este SKU; se toma como sin pronóstico. Se muestra como faltante en la hoja de comparación y no cuenta en las métricas.
A13: HP2/01/115gsm/2150mm | B13: SALI | C13: 2026-09 | D13: 58 | E13: Modelo interno sin pronóstico | F13: El modelo interno tiene 0 en todos los meses para este SKU; se toma como sin pronóstico. Se muestra como faltante en la hoja de comparación y no cuenta en las métricas.
... A57: KS/01/215gsm/2450mm | B57: SALM | C57: 2026-09 | D57: 70 | E57: Subgrado distinto | F57: El nombre del SKU no coincide con los datos de consumo porque cambia el subgrado (en los datos: KS/257/215gsm/2450mm). No se cruzó: pendiente de confirmar con el planificador.

Sheet Resumen por planta
A1: Planta | B1: SKU en las tres fuentes | C1: Real (TO) | D1: Planificador (TO) | E1: Modelo interno (TO) | F1: Nuestro modelo (TO) | G1: WAPE planificador | H1: WAPE modelo interno | I1: WAPE nuestro modelo | J1: Acierto planificador | K1: Acierto modelo interno | L1: Acierto nuestro modelo | M1: Sesgo planificador | N1: Sesgo modelo interno | O1: Sesgo nuestro modelo
A2: Todas | B2: =COUNTIFS('Comparación'!$H$2:$H$444,TRUE) | C2: =SUMIFS('Comparación'!$D$2:$D$444,'Comparación'!$H$2:$H$444,TRUE) | D2: =SUMIFS('Comparación'!$E$2:$E$444,'Comparación'!$H$2:$H$444,TRUE) | E2: =SUMIFS('Comparación'!$F$2:$F$444,'Comparación'!$H$2:$H$444,TRUE) | F2: =SUMIFS('Comparación'!$G$2:$G$444,'Comparación'!$H$2:$H$444,TRUE) | G2: =SUMIFS('Comparación'!$L$2:$L$444,'Comparación'!$H$2:$H$444,TRUE)/$C2 | H2: =SUMIFS('Comparación'!$M$2:$M$444,'Comparación'!$H$2:$H$444,TRUE)/$C2 | I2: =SUMIFS('Comparación'!$N$2:$N$444,'Comparación'!$H$2:$H$444,TRUE)/$C2 | J2: =1-G2 | K2: =1-H2 | L2: =1-I2 | M2: =D2/C2-1 | N2: =E2/C2-1 | O2: =F2/C2-1
A3: PCEL | B3: =COUNTIFS('Comparación'!$B$2:$B$444,$A3,'Comparación'!$H$2:$H$444,TRUE) | C3: =SUMIFS('Comparación'!$D$2:$D$444,'Comparación'!$B$2:$B$444,$A3,'Comparación'!$H$2:$H$444,TRUE) | D3: =SUMIFS('Comparación'!$E$2:$E$444,'Comparación'!$B$2:$B$444,$A3,'Comparación'!$H$2:$H$444,TRUE) | E3: =SUMIFS('Comparación'!$F$2:$F$444,'Comparación'!$B$2:$B$444,$A3,'Comparación'!$H$2:$H$444,TRUE) | F3: =SUMIFS('Comparación'!$G$2:$G$444,'Comparación'!$B$2:$B$444,$A3,'Comparación'!$H$2:$H$444,TRUE) | G3: =SUMIFS('Comparación'!$L$2:$L$444,'Comparación'!$B$2:$B$444,$A3,'Comparación'!$H$2:$H$444,TRUE)/$C3 | H3: =SUMIFS('Comparación'!$M$2:$M$444,'Comparación'!$B$2:$B$444,$A3,'Comparación'!$H$2:$H$444,TRUE)/$C3 | I3: =SUMIFS('Comparación'!$N$2:$N$444,'Comparación'!$B$2:$B$444,$A3,'Comparación'!$H$2:$H$444,TRUE)/$C3 | J3: =1-G3 | K3: =1-H3 | L3: =1-I3 | M3: =D3/C3-1 | N3: =E3/C3-1 | O3: =F3/C3-1
A4: SALC | B4: =COUNTIFS('Comparación'!$B$2:$B$444,$A4,'Comparación'!$H$2:$H$444,TRUE) | C4: =SUMIFS('Comparación'!$D$2:$D$444,'Comparación'!$B$2:$B$444,$A4,'Comparación'!$H$2:$H$444,TRUE) | D4: =SUMIFS('Comparación'!$E$2:$E$444,'Comparación'!$B$2:$B$444,$A4,'Comparación'!$H$2:$H$444,TRUE) | E4: =SUMIFS('Comparación'!$F$2:$F$444,'Comparación'!$B$2:$B$444,$A4,'Comparación'!$H$2:$H$444,TRUE) | F4: =SUMIFS('Comparación'!$G$2:$G$444,'Comparación'!$B$2:$B$444,$A4,'Comparación'!$H$2:$H$444,TRUE) | G4: =SUMIFS('Comparación'!$L$2:$L$444,'Comparación'!$B$2:$B$444,$A4,'Comparación'!$H$2:$H$444,TRUE)/$C4 | H4: =SUMIFS('Comparación'!$M$2:$M$444,'Comparación'!$B$2:$B$444,$A4,'Comparación'!$H$2:$H$444,TRUE)/$C4 | I4: =SUMIFS('Comparación'!$N$2:$N$444,'Comparación'!$B$2:$B$444,$A4,'Comparación'!$H$2:$H$444,TRUE)/$C4 | J4: =1-G4 | K4: =1-H4 | L4: =1-I4 | M4: =D4/C4-1 | N4: =E4/C4-1 | O4: =F4/C4-1
A5: SALI | B5: =COUNTIFS('Comparación'!$B$2:$B$444,$A5,'Comparación'!$H$2:$H$444,TRUE) | C5: =SUMIFS('Comparación'!$D$2:$D$444,'Comparación'!$B$2:$B$444,$A5,'Comparación'!$H$2:$H$444,TRUE) | D5: =SUMIFS('Comparación'!$E$2:$E$444,'Comparación'!$B$2:$B$444,$A5,'Comparación'!$H$2:$H$444,TRUE) | E5: =SUMIFS('Comparación'!$F$2:$F$444,'Comparación'!$B$2:$B$444,$A5,'Comparación'!$H$2:$H$444,TRUE) | F5: =SUMIFS('Comparación'!$G$2:$G$444,'Comparación'!$B$2:$B$444,$A5,'Comparación'!$H$2:$H$444,TRUE) | G5: =SUMIFS('Comparación'!$L$2:$L$444,'Comparación'!$B$2:$B$444,$A5,'Comparación'!$H$2:$H$444,TRUE)/$C5 | H5: =SUMIFS('Comparación'!$M$2:$M$444,'Comparación'!$B$2:$B$444,$A5,'Comparación'!$H$2:$H$444,TRUE)/$C5 | I5: =SUMIFS('Comparación'!$N$2:$N$444,'Comparación'!$B$2:$B$444,$A5,'Comparación'!$H$2:$H$444,TRUE)/$C5 | J5: =1-G5 | K5: =1-H5 | L5: =1-I5 | M5: =D5/C5-1 | N5: =E5/C5-1 | O5: =F5/C5-1
A6: SALM | B6: =COUNTIFS('Comparación'!$B$2:$B$444,$A6,'Comparación'!$H$2:$H$444,TRUE) | C6: =SUMIFS('Comparación'!$D$2:$D$444,'Comparación'!$B$2:$B$444,$A6,'Comparación'!$H$2:$H$444,TRUE) | D6: =SUMIFS('Comparación'!$E$2:$E$444,'Comparación'!$B$2:$B$444,$A6,'Comparación'!$H$2:$H$444,TRUE) | E6: =SUMIFS('Comparación'!$F$2:$F$444,'Comparación'!$B$2:$B$444,$A6,'Comparación'!$H$2:$H$444,TRUE) | F6: =SUMIFS('Comparación'!$G$2:$G$444,'Comparación'!$B$2:$B$444,$A6,'Comparación'!$H$2:$H$444,TRUE) | G6: =SUMIFS('Comparación'!$L$2:$L$444,'Comparación'!$B$2:$B$444,$A6,'Comparación'!$H$2:$H$444,TRUE)/$C6 | H6: =SUMIFS('Comparación'!$M$2:$M$444,'Comparación'!$B$2:$B$444,$A6,'Comparación'!$H$2:$H$444,TRUE)/$C6 | I6: =SUMIFS('Comparación'!$N$2:$N$444,'Comparación'!$B$2:$B$444,$A6,'Comparación'!$H$2:$H$444,TRUE)/$C6 | J6: =1-G6 | K6: =1-H6 | L6: =1-I6 | M6: =D6/C6-1 | N6: =E6/C6-1 | O6: =F6/C6-1
A7: SBUR | B7: =COUNTIFS('Comparación'!$B$2:$B$444,$A7,'Comparación'!$H$2:$H$444,TRUE) | C7: =SUMIFS('Comparación'!$D$2:$D$444,'Comparación'!$B$2:$B$444,$A7,'Comparación'!$H$2:$H$444,TRUE) | D7: =SUMIFS('Comparación'!$E$2:$E$444,'Comparación'!$B$2:$B$444,$A7,'Comparación'!$H$2:$H$444,TRUE) | E7: =SUMIFS('Comparación'!$F$2:$F$444,'Comparación'!$B$2:$B$444,$A7,'Comparación'!$H$2:$H$444,TRUE) | F7: =SUMIFS('Comparación'!$G$2:$G$444,'Comparación'!$B$2:$B$444,$A7,'Comparación'!$H$2:$H$444,TRUE) | G7: =SUMIFS('Comparación'!$L$2:$L$444,'Comparación'!$B$2:$B$444,$A7,'Comparación'!$H$2:$H$444,TRUE)/$C7 | H7: =SUMIFS('Comparación'!$M$2:$M$444,'Comparación'!$B$2:$B$444,$A7,'Comparación'!$H$2:$H$444,TRUE)/$C7 | I7: =SUMIFS('Comparación'!$N$2:$N$444,'Comparación'!$B$2:$B$444,$A7,'Comparación'!$H$2:$H$444,TRUE)/$C7 | J7: =1-G7 | K7: =1-H7 | L7: =1-I7 | M7: =D7/C7-1 | N7: =E7/C7-1 | O7: =F7/C7-1
A8: SCAN | B8: =COUNTIFS('Comparación'!$B$2:$B$444,$A8,'Comparación'!$H$2:$H$444,TRUE) | C8: =SUMIFS('Comparación'!$D$2:$D$444,'Comparación'!$B$2:$B$444,$A8,'Comparación'!$H$2:$H$444,TRUE) | D8: =SUMIFS('Comparación'!$E$2:$E$444,'Comparación'!$B$2:$B$444,$A8,'Comparación'!$H$2:$H$444,TRUE) | E8: =SUMIFS('Comparación'!$F$2:$F$444,'Comparación'!$B$2:$B$444,$A8,'Comparación'!$H$2:$H$444,TRUE) | F8: =SUMIFS('Comparación'!$G$2:$G$444,'Comparación'!$B$2:$B$444,$A8,'Comparación'!$H$2:$H$444,TRUE) | G8: =SUMIFS('Comparación'!$L$2:$L$444,'Comparación'!$B$2:$B$444,$A8,'Comparación'!$H$2:$H$444,TRUE)/$C8 | H8: =SUMIFS('Comparación'!$M$2:$M$444,'Comparación'!$B$2:$B$444,$A8,'Comparación'!$H$2:$H$444,TRUE)/$C8 | I8: =SUMIFS('Comparación'!$N$2:$N$444,'Comparación'!$B$2:$B$444,$A8,'Comparación'!$H$2:$H$444,TRUE)/$C8 | J8: =1-G8 | K8: =1-H8 | L8: =1-I8 | M8: =D8/C8-1 | N8: =E8/C8-1 | O8: =F8/C8-1
A9: SCOC | B9: =COUNTIFS('Comparación'!$B$2:$B$444,$A9,'Comparación'!$H$2:$H$444,TRUE) | C9: =SUMIFS('Comparación'!$D$2:$D$444,'Comparación'!$B$2:$B$444,$A9,'Comparación'!$H$2:$H$444,TRUE) | D9: =SUMIFS('Comparación'!$E$2:$E$444,'Comparación'!$B$2:$B$444,$A9,'Comparación'!$H$2:$H$444,TRUE) | E9: =SUMIFS('Comparación'!$F$2:$F$444,'Comparación'!$B$2:$B$444,$A9,'Comparación'!$H$2:$H$444,TRUE) | F9: =SUMIFS('Comparación'!$G$2:$G$444,'Comparación'!$B$2:$B$444,$A9,'Comparación'!$H$2:$H$444,TRUE) | G9: =SUMIFS('Comparación'!$L$2:$L$444,'Comparación'!$B$2:$B$444,$A9,'Comparación'!$H$2:$H$444,TRUE)/$C9 | H9: =SUMIFS('Comparación'!$M$2:$M$444,'Comparación'!$B$2:$B$444,$A9,'Comparación'!$H$2:$H$444,TRUE)/$C9 | I9: =SUMIFS('Comparación'!$N$2:$N$444,'Comparación'!$B$2:$B$444,$A9,'Comparación'!$H$2:$H$444,TRUE)/$C9 | J9: =1-G9 | K9: =1-H9 | L9: =1-I9 | M9: =D9/C9-1 | N9: =E9/C9-1 | O9: =F9/C9-1
A10: SCVA | B10: =COUNTIFS('Comparación'!$B$2:$B$444,$A10,'Comparación'!$H$2:$H$444,TRUE) | C10: =SUMIFS('Comparación'!$D$2:$D$444,'Comparación'!$B$2:$B$444,$A10,'Comparación'!$H$2:$H$444,TRUE) | D10: =SUMIFS('Comparación'!$E$2:$E$444,'Comparación'!$B$2:$B$444,$A10,'Comparación'!$H$2:$H$444,TRUE) | E10: =SUMIFS('Comparación'!$F$2:$F$444,'Comparación'!$B$2:$B$444,$A10,'Comparación'!$H$2:$H$444,TRUE) | F10: =SUMIFS('Comparación'!$G$2:$G$444,'Comparación'!$B$2:$B$444,$A10,'Comparación'!$H$2:$H$444,TRUE) | G10: =SUMIFS('Comparación'!$L$2:$L$444,'Comparación'!$B$2:$B$444,$A10,'Comparación'!$H$2:$H$444,TRUE)/$C10 | H10: =SUMIFS('Comparación'!$M$2:$M$444,'Comparación'!$B$2:$B$444,$A10,'Comparación'!$H$2:$H$444,TRUE)/$C10 | I10: =SUMIFS('Comparación'!$N$2:$N$444,'Comparación'!$B$2:$B$444,$A10,'Comparación'!$H$2:$H$444,TRUE)/$C10 | J10: =1-G10 | K10: =1-H10 | L10: =1-I10 | M10: =D10/C10-1 | N10: =E10/C10-1 | O10: =F10/C10-1
A11: SPAL | B11: =COUNTIFS('Comparación'!$B$2:$B$444,$A11,'Comparación'!$H$2:$H$444,TRUE) | C11: =SUMIFS('Comparación'!$D$2:$D$444,'Comparación'!$B$2:$B$444,$A11,'Comparación'!$H$2:$H$444,TRUE) | D11: =SUMIFS('Comparación'!$E$2:$E$444,'Comparación'!$B$2:$B$444,$A11,'Comparación'!$H$2:$H$444,TRUE) | E11: =SUMIFS('Comparación'!$F$2:$F$444,'Comparación'!$B$2:$B$444,$A11,'Comparación'!$H$2:$H$444,TRUE) | F11: =SUMIFS('Comparación'!$G$2:$G$444,'Comparación'!$B$2:$B$444,$A11,'Comparación'!$H$2:$H$444,TRUE) | G11: =SUMIFS('Comparación'!$L$2:$L$444,'Comparación'!$B$2:$B$444,$A11,'Comparación'!$H$2:$H$444,TRUE)/$C11 | H11: =SUMIFS('Comparación'!$M$2:$M$444,'Comparación'!$B$2:$B$444,$A11,'Comparación'!$H$2:$H$444,TRUE)/$C11 | I11: =SUMIFS('Comparación'!$N$2:$N$444,'Comparación'!$B$2:$B$444,$A11,'Comparación'!$H$2:$H$444,TRUE)/$C11 | J11: =1-G11 | K11: =1-H11 | L11: =1-I11 | M11: =D11/C11-1 | N11: =E11/C11-1 | O11: =F11/C11-1
A12: SQUA | B12: =COUNTIFS('Comparación'!$B$2:$B$444,$A12,'Comparación'!$H$2:$H$444,TRUE) | C12: =SUMIFS('Comparación'!$D$2:$D$444,'Comparación'!$B$2:$B$444,$A12,'Comparación'!$H$2:$H$444,TRUE) | D12: =SUMIFS('Comparación'!$E$2:$E$444,'Comparación'!$B$2:$B$444,$A12,'Comparación'!$H$2:$H$444,TRUE) | E12: =SUMIFS('Comparación'!$F$2:$F$444,'Comparación'!$B$2:$B$444,$A12,'Comparación'!$H$2:$H$444,TRUE) | F12: =SUMIFS('Comparación'!$G$2:$G$444,'Comparación'!$B$2:$B$444,$A12,'Comparación'!$H$2:$H$444,TRUE) | G12: =SUMIFS('Comparación'!$L$2:$L$444,'Comparación'!$B$2:$B$444,$A12,'Comparación'!$H$2:$H$444,TRUE)/$C12 | H12: =SUMIFS('Comparación'!$M$2:$M$444,'Comparación'!$B$2:$B$444,$A12,'Comparación'!$H$2:$H$444,TRUE)/$C12 | I12: =SUMIFS('Comparación'!$N$2:$N$444,'Comparación'!$B$2:$B$444,$A12,'Comparación'!$H$2:$H$444,TRUE)/$C12 | J12: =1-G12 | K12: =1-H12 | L12: =1-I12 | M12: =D12/C12-1 | N12: =E12/C12-1 | O12: =F12/C12-1
A13: SVIG | B13: =COUNTIFS('Comparación'!$B$2:$B$444,$A13,'Comparación'!$H$2:$H$444,TRUE) | C13: =SUMIFS('Comparación'!$D$2:$D$444,'Comparación'!$B$2:$B$444,$A13,'Comparación'!$H$2:$H$444,TRUE) | D13: =SUMIFS('Comparación'!$E$2:$E$444,'Comparación'!$B$2:$B$444,$A13,'Comparación'!$H$2:$H$444,TRUE) | E13: =SUMIFS('Comparación'!$F$2:$F$444,'Comparación'!$B$2:$B$444,$A13,'Comparación'!$H$2:$H$444,TRUE) | F13: =SUMIFS('Comparación'!$G$2:$G$444,'Comparación'!$B$2:$B$444,$A13,'Comparación'!$H$2:$H$444,TRUE) | G13: =SUMIFS('Comparación'!$L$2:$L$444,'Comparación'!$B$2:$B$444,$A13,'Comparación'!$H$2:$H$444,TRUE)/$C13 | H13: =SUMIFS('Comparación'!$M$2:$M$444,'Comparación'!$B$2:$B$444,$A13,'Comparación'!$H$2:$H$444,TRUE)/$C13 | I13: =SUMIFS('Comparación'!$N$2:$N$444,'Comparación'!$B$2:$B$444,$A13,'Comparación'!$H$2:$H$444,TRUE)/$C13 | J13: =1-G13 | K13: =1-H13 | L13: =1-I13 | M13: =D13/C13-1 | N13: =E13/C13-1 | O13: =F13/C13-1
